scripts/test.in
1
o
S 123 GOOG 2999 10
S 124 GOOG 2888 25
S 1125 GOOG 2777 30
S 1126 GOOG 3333 30
S 1127 GOOG 2222 30
S 1128 GOOG 2111 30
S 1129 GOOG 1111 30
S 11210 GOOG 11 30
S 11211 GOOG 22 30
S 11212 GOOG 333 30
S 11213 GOOG 444 30
S 11214 GOOG 5555 30
B 125 GOOG 2777 30
B 126 GOOG 3333 30
B 127 GOOG 2222 30
B 128 GOOG 2111 30
B 129 GOOG 1111 30
B 1210 GOOG 11 30
B 1211 GOOG 22 30
B 1212 GOOG 333 30
B 1213 GOOG 444 30
B 1214 GOOG 5555 30
x
