tests/multisell_singlebuy.in
40
o
0 S 8888 ABC 8888 1000
1 S 9999 ABC 9999 1000
.
1 B 1 ABC 8888 30
2 B 2 ABC 8888 30
3 B 3 ABC 8888 30
4 B 4 ABC 8888 30
5 B 5 ABC 8888 30
6 B 6 ABC 8888 30
7 B 7 ABC 8888 30
8 B 8 ABC 8888 30
9 B 9 ABC 8888 30
10 B 10 ABC 8888 30
11 B 11 ABC 8888 30
12 B 12 ABC 8888 30
13 B 13 ABC 8888 30
14 B 14 ABC 8888 30
15 B 15 ABC 8888 30
16 B 16 ABC 8888 30
17 B 17 ABC 8888 30
18 B 18 ABC 8888 30
19 B 19 ABC 8888 30
20 B 20 ABC 8888 30
21 B 21 ABC 8888 30
22 B 22 ABC 8888 30
23 B 23 ABC 8888 30
24 B 24 ABC 8888 30
25 B 25 ABC 8888 30
26 B 26 ABC 8888 30
27 B 27 ABC 8888 30
28 B 28 ABC 8888 30
29 B 29 ABC 8888 30
30 B 30 ABC 8888 30
31 B 31 ABC 8888 30
32 B 32 ABC 8888 30
33 B 33 ABC 8888 30
34 B 34 ABC 8888 30
35 B 35 ABC 8888 30
36 B 36 ABC 8888 30
37 B 37 ABC 8888 30
38 B 38 ABC 8888 30
39 B 39 ABC 8888 30
1 B 91 ABC 99999 30
2 B 92 ABC 99999 30
3 B 93 ABC 99999 30
4 B 94 ABC 99999 30
5 B 95 ABC 99999 30
6 B 96 ABC 99999 30
7 B 97 ABC 99999 30
8 B 98 ABC 99999 30
9 B 99 ABC 99999 30
10 B 910 ABC 99999 30
11 B 911 ABC 99999 30
12 B 912 ABC 99999 30
13 B 913 ABC 99999 30
14 B 914 ABC 99999 30
15 B 915 ABC 99999 30
16 B 916 ABC 99999 30
17 B 917 ABC 99999 30
18 B 918 ABC 99999 30
19 B 919 ABC 99999 30
20 B 920 ABC 99999 30
21 B 921 ABC 99999 30
22 B 922 ABC 99999 30
23 B 923 ABC 99999 30
24 B 924 ABC 99999 30
25 B 925 ABC 99999 30
26 B 926 ABC 99999 30
27 B 927 ABC 99999 30
28 B 928 ABC 99999 30
29 B 929 ABC 99999 30
30 B 930 ABC 99999 30
31 B 931 ABC 99999 30
32 B 932 ABC 99999 30
33 B 933 ABC 99999 30
34 B 934 ABC 99999 30
35 B 935 ABC 99999 30
36 B 936 ABC 99999 30
37 B 937 ABC 99999 30
38 B 938 ABC 99999 30
39 B 939 ABC 99999 30
x
