tests/single-symbol.in
40
o
9 B 100 NTRR 2738 29
16 S 101 NTRR 2860 11
20 B 102 NTRR 2822 12
14 B 103 NTRR 2760 28
5 B 104 NTRR 2839 18
16 C 101
30 S 105 NTRR 2820 28
20 B 106 NTRR 2883 15
9 C 100
30 C 105
28 B 107 NTRR 2823 23
9 B 108 NTRR 2848 30
14 C 103
5 S 109 NTRR 2870 21
33 S 110 NTRR 2912 17
30 S 111 NTRR 2783 30
1 S 112 NTRR 2818 25
12 S 113 NTRR 2885 29
1 C 112
5 C 109
30 C 105
33 B 114 NTRR 2850 16
25 B 115 NTRR 2841 29
27 S 116 NTRR 2854 20
5 C 104
6 S 117 NTRR 2901 11
22 B 118 NTRR 2912 23
14 C 103
14 B 119 NTRR 2752 12
22 C 118
37 B 120 NTRR 2831 17
15 B 121 NTRR 2867 16
21 B 122 NTRR 2734 15
31 B 123 NTRR 2766 18
24 B 124 NTRR 2883 30
16 S 125 NTRR 2820 22
6 B 126 NTRR 2736 29
21 C 122
20 C 102
19 S 127 NTRR 2789 21
31 C 123
24 S 128 NTRR 2845 23
31 C 123
25 B 129 NTRR 2836 20
16 C 125
38 B 130 NTRR 2910 19
27 B 131 NTRR 2901 12
35 S 132 NTRR 2736 24
25 C 115
15 S 133 NTRR 2838 11
28 S 134 NTRR 2912 21
15 B 135 NTRR 2776 13
20 S 136 NTRR 2758 22
6 B 137 NTRR 2903 23
12 B 138 NTRR 2877 24
5 C 109
20 C 102
12 C 113
9 S 139 NTRR 2769 17
29 B 140 NTRR 2896 12
16 C 125
20 C 136
7 B 141 NTRR 2811 30
21 B 142 NTRR 2902 19
24 S 143 NTRR 2910 17
21 B 144 NTRR 2768 12
7 S 145 NTRR 2795 19
34 S 146 NTRR 2750 24
28 S 147 NTRR 2904 20
12 C 138
10 S 148 NTRR 2927 23
6 C 137
3 B 149 NTRR 2752 27
25 C 115
2 S 150 NTRR 2862 14
13 B 151 NTRR 2826 30
28 B 152 NTRR 2772 16
15 B 153 NTRR 2792 28
28 C 107
37 S 154 NTRR 2884 18
21 C 144
21 C 142
27 B 155 NTRR 2857 23
31 C 123
34 B 156 NTRR 2827 18
10 C 148
12 S 157 NTRR 2761 30
13 C 151
12 S 158 NTRR 2904 10
6 S 159 NTRR 2777 25
32 B 160 NTRR 2771 19
38 S 161 NTRR 2779 30
24 C 128
12 S 162 NTRR 2903 20
31 S 163 NTRR 2902 18
38 S 164 NTRR 2797 19
33 S 165 NTRR 2781 23
22 S 166 NTRR 2864 29
2 S 167 NTRR 2930 12
24 S 168 NTRR 2759 20
34 C 156
21 C 142
38 C 161
12 C 113
29 B 169 NTRR 2883 12
28 C 107
26 B 170 NTRR 2906 14
12 S 171 NTRR 2906 29
21 B 172 NTRR 2801 14
36 B 173 NTRR 2766 27
31 S 174 NTRR 2841 14
31 S 175 NTRR 2926 20
2 C 150
20 S 176 NTRR 2899 18
7 S 177 NTRR 2794 16
9 S 178 NTRR 2780 12
27 B 179 NTRR 2905 27
3 B 180 NTRR 2748 12
18 B 181 NTRR 2881 13
17 B 182 NTRR 2879 22
29 B 183 NTRR 2865 17
12 C 138
20 C 176
21 S 184 NTRR 2893 24
18 B 185 NTRR 2759 24
35 C 132
28 C 152
31 B 186 NTRR 2895 15
9 B 187 NTRR 2769 16
11 S 188 NTRR 2901 12
11 S 189 NTRR 2893 25
14 S 190 NTRR 2863 18
26 B 191 NTRR 2848 15
31 C 123
16 C 125
15 C 121
19 S 192 NTRR 2777 16
12 B 193 NTRR 2748 20
26 S 194 NTRR 2866 11
29 S 195 NTRR 2740 13
36 B 196 NTRR 2842 20
21 C 172
32 B 197 NTRR 2816 28
12 C 113
19 S 198 NTRR 2889 15
5 S 199 NTRR 2748 19
32 C 160
15 C 135
18 S 200 NTRR 2730 27
9 B 201 NTRR 2927 10
37 S 202 NTRR 2916 27
9 S 203 NTRR 2802 29
15 B 204 NTRR 2824 15
19 C 192
38 S 205 NTRR 2809 26
32 C 197
6 B 206 NTRR 2856 13
31 S 207 NTRR 2802 19
24 C 128
5 C 109
29 C 195
7 B 208 NTRR 2807 27
0 B 209 NTRR 2740 13
0 C 209
6 C 117
3 B 210 NTRR 2828 15
24 B 211 NTRR 2795 23
22 S 212 NTRR 2866 18
28 B 213 NTRR 2916 29
23 B 214 NTRR 2736 11
7 C 208
16 C 125
22 S 215 NTRR 2834 29
30 S 216 NTRR 2822 24
36 S 217 NTRR 2916 23
7 C 208
25 C 129
6 C 159
18 S 218 NTRR 2831 24
24 B 219 NTRR 2825 17
8 B 220 NTRR 2799 24
7 B 221 NTRR 2905 15
24 S 222 NTRR 2835 12
13 B 223 NTRR 2754 20
39 B 224 NTRR 2732 19
6 C 137
6 C 117
3 S 225 NTRR 2770 17
20 S 226 NTRR 2865 22
20 C 226
26 S 227 NTRR 2893 22
18 S 228 NTRR 2859 22
22 C 215
32 C 160
30 C 105
14 B 229 NTRR 2731 23
16 S 230 NTRR 2899 24
28 C 147
15 S 231 NTRR 2824 12
25 S 232 NTRR 2745 28
14 C 190
28 C 213
7 B 233 NTRR 2872 24
24 S 234 NTRR 2866 29
0 B 235 NTRR 2872 21
3 S 236 NTRR 2864 17
28 C 152
17 C 182
21 C 122
26 B 237 NTRR 2899 30
7 C 208
0 C 235
17 B 238 NTRR 2759 18
38 B 239 NTRR 2743 15
30 C 216
5 S 240 NTRR 2896 20
19 S 241 NTRR 2855 18
26 C 227
37 S 242 NTRR 2749 13
8 B 243 NTRR 2812 27
37 B 244 NTRR 2794 21
8 S 245 NTRR 2743 16
28 S 246 NTRR 2785 19
8 B 247 NTRR 2843 23
28 S 248 NTRR 2804 12
34 C 146
13 S 249 NTRR 2914 29
3 S 250 NTRR 2868 18
24 C 124
33 S 251 NTRR 2787 29
14 C 119
9 S 252 NTRR 2880 10
24 B 253 NTRR 2776 12
21 S 254 NTRR 2881 30
34 B 255 NTRR 2813 20
6 C 137
11 C 188
14 B 256 NTRR 2848 11
34 S 257 NTRR 2791 21
32 B 258 NTRR 2811 11
27 B 259 NTRR 2846 30
26 C 237
28 C 152
23 B 260 NTRR 2854 23
12 C 157
2 B 261 NTRR 2828 29
6 S 262 NTRR 2887 10
30 S 263 NTRR 2897 21
16 S 264 NTRR 2736 23
36 C 196
0 C 209
30 C 263
28 S 265 NTRR 2801 20
6 S 266 NTRR 2735 29
2 S 267 NTRR 2848 12
8 B 268 NTRR 2864 12
13 B 269 NTRR 2896 26
0 C 235
38 B 270 NTRR 2828 22
25 B 271 NTRR 2801 20
16 S 272 NTRR 2841 24
3 S 273 NTRR 2850 21
19 S 274 NTRR 2842 29
28 B 275 NTRR 2840 24
18 C 218
0 C 235
37 C 244
33 B 276 NTRR 2862 25
13 S 277 NTRR 2794 30
34 B 278 NTRR 2820 21
8 C 245
22 S 279 NTRR 2926 12
36 C 196
12 B 280 NTRR 2820 26
35 S 281 NTRR 2766 27
37 C 202
28 C 107
16 C 264
6 B 282 NTRR 2782 27
9 S 283 NTRR 2870 16
34 B 284 NTRR 2744 24
12 C 138
33 S 285 NTRR 2909 23
33 C 110
35 C 281
34 B 286 NTRR 2746 24
15 C 204
5 C 240
37 C 154
10 S 287 NTRR 2773 25
21 S 288 NTRR 2756 27
34 B 289 NTRR 2927 14
6 C 266
5 S 290 NTRR 2758 19
30 C 105
12 S 291 NTRR 2891 13
6 C 159
7 B 292 NTRR 2901 26
3 S 293 NTRR 2805 22
24 B 294 NTRR 2919 12
28 S 295 NTRR 2918 13
19 S 296 NTRR 2926 25
10 B 297 NTRR 2827 15
5 B 298 NTRR 2808 23
12 B 299 NTRR 2919 30
4 B 300 NTRR 2912 19
31 B 301 NTRR 2740 26
11 B 302 NTRR 2845 16
0 B 303 NTRR 2882 16
8 C 247
34 C 286
29 B 304 NTRR 2918 29
3 C 225
13 C 277
4 S 305 NTRR 2784 19
26 S 306 NTRR 2889 21
5 B 307 NTRR 2798 30
18 C 185
19 S 308 NTRR 2884 13
22 B 309 NTRR 2785 20
33 B 310 NTRR 2856 17
25 S 311 NTRR 2781 18
22 B 312 NTRR 2825 25
3 B 313 NTRR 2796 23
13 B 314 NTRR 2810 22
15 C 133
14 B 315 NTRR 2846 27
14 S 316 NTRR 2846 28
29 B 317 NTRR 2819 14
23 B 318 NTRR 2735 13
32 B 319 NTRR 2743 27
23 C 318
30 B 320 NTRR 2779 18
34 C 156
39 B 321 NTRR 2801 10
29 C 169
38 C 239
36 B 322 NTRR 2817 30
1 S 323 NTRR 2771 20
26 B 324 NTRR 2822 20
36 B 325 NTRR 2750 27
9 B 326 NTRR 2882 16
28 B 327 NTRR 2778 29
34 B 328 NTRR 2782 25
12 C 193
27 B 329 NTRR 2863 24
20 S 330 NTRR 2775 11
13 C 269
18 S 331 NTRR 2915 20
17 C 182
32 B 332 NTRR 2820 23
7 C 141
23 B 333 NTRR 2804 27
10 C 297
24 C 143
24 B 334 NTRR 2788 13
1 B 335 NTRR 2864 22
39 S 336 NTRR 2882 18
36 B 337 NTRR 2772 11
11 B 338 NTRR 2828 28
19 C 241
36 C 173
20 C 106
26 B 339 NTRR 2804 18
36 B 340 NTRR 2886 16
29 C 169
29 S 341 NTRR 2762 19
5 C 199
11 S 342 NTRR 2914 22
7 B 343 NTRR 2782 21
6 B 344 NTRR 2769 20
28 C 147
29 S 345 NTRR 2864 10
29 C 345
16 S 346 NTRR 2924 17
28 B 347 NTRR 2896 24
7 C 292
28 C 248
20 S 348 NTRR 2745 17
25 C 115
25 B 349 NTRR 2872 29
3 B 350 NTRR 2861 12
14 C 229
10 C 287
21 B 351 NTRR 2776 13
37 B 352 NTRR 2776 26
19 C 274
12 B 353 NTRR 2910 12
6 B 354 NTRR 2804 17
28 C 275
16 S 355 NTRR 2918 10
34 B 356 NTRR 2909 23
23 B 357 NTRR 2912 11
14 B 358 NTRR 2779 28
9 B 359 NTRR 2753 24
12 B 360 NTRR 2757 15
0 B 361 NTRR 2863 23
29 S 362 NTRR 2914 19
10 B 363 NTRR 2780 10
30 S 364 NTRR 2849 11
36 B 365 NTRR 2871 18
30 B 366 NTRR 2842 23
13 B 367 NTRR 2786 17
35 S 368 NTRR 2929 19
36 S 369 NTRR 2895 19
33 S 370 NTRR 2803 18
2 S 371 NTRR 2771 16
9 C 139
29 B 372 NTRR 2810 20
12 S 373 NTRR 2906 27
7 S 374 NTRR 2908 23
5 C 104
18 S 375 NTRR 2837 27
21 B 376 NTRR 2783 27
6 C 126
6 S 377 NTRR 2787 26
31 B 378 NTRR 2801 17
29 B 379 NTRR 2793 15
26 C 324
33 C 285
20 S 380 NTRR 2882 21
21 B 381 NTRR 2805 13
13 B 382 NTRR 2801 13
12 B 383 NTRR 2909 13
16 S 384 NTRR 2776 12
10 B 385 NTRR 2917 15
29 B 386 NTRR 2838 12
34 S 387 NTRR 2837 18
6 B 388 NTRR 2880 25
27 B 389 NTRR 2854 22
18 B 390 NTRR 2775 26
0 B 391 NTRR 2909 14
11 C 338
4 S 392 NTRR 2846 10
30 C 366
10 S 393 NTRR 2839 30
22 C 118
6 C 262
10 S 394 NTRR 2854 16
0 B 395 NTRR 2891 12
3 C 313
29 C 195
16 B 396 NTRR 2884 11
18 B 397 NTRR 2893 14
21 C 172
28 C 147
26 S 398 NTRR 2841 11
13 B 399 NTRR 2755 25
38 B 400 NTRR 2919 22
3 C 273
7 C 177
16 C 272
17 S 401 NTRR 2789 14
36 S 402 NTRR 2787 23
30 B 403 NTRR 2879 15
23 S 404 NTRR 2864 15
20 B 405 NTRR 2795 19
31 S 406 NTRR 2733 15
